<?xml version="1.0" encoding="utf-8"?>
<robot
  name="atom01urdf">
  <link
    name="base_link">
    <inertial>
      <origin
        xyz="-0.04829206 -0.00009266  -0.00976163"
        rpy="0 0 0" />
      <mass
        value="5.50170905 " />
    <inertia ixx="0.02871150" ixy="-0.00002867" ixz="-0.00432640"
           iyy="0.02683348" iyz="-0.00000804"
           izz="0.03830469"/>
    </inertial>
    <visual>
      <origin
        xyz="0 0 0"
        rpy="0 0 0" />
      <geometry>
        <mesh
          filename="../meshes/base_link.STL" />
      </geometry>
      <material
        name="">
        <color
          rgba="0.898039215686275 0.917647058823529 0.929411764705882 1" />
      </material>
    </visual>
    <collision>
      <origin
        xyz="0 0 0"
        rpy="0 0 0" />
      <geometry>
        <mesh
          filename="../meshes/base_link.STL" />
      </geometry>
    </collision>
  </link>
  <link
    name="left_thigh_yaw_link">
    <inertial>
      <origin
        xyz="-0.03475324 -0.00013158  -0.05708821"
        rpy="0 0 0" />
      <mass
        value="1.68565743 " />
      <inertia
        ixx=" 0.007179"
        ixy="-0.00000776"
        ixz="-0.00378592"
        iyy="0.00890779"
        iyz="-0.00001246"
        izz="0.00327069" />
    </inertial>
    <visual>
      <origin
        xyz="0 0 0"
        rpy="0 0 0" />
      <geometry>
        <mesh
          filename="../meshes/left_thigh_yaw_link.STL" />
      </geometry>
      <material
        name="">
        <color
          rgba="0.898039215686275 0.917647058823529 0.929411764705882 1" />
      </material>
    </visual>
    <!-- <collision>
      <origin
        xyz="0 0 0"
        rpy="0 0 0" />
      <geometry>
        <mesh
          filename="../meshes/left_thigh_yaw_link.STL" />
      </geometry>
    </collision> -->
  </link>
  <joint
    name="left_thigh_yaw_joint"
    type="revolute">
    <origin
      xyz="-0.071093 0.0725 -0.051778"
      rpy="0 0 0" />
    <parent
      link="base_link" />
    <child
      link="left_thigh_yaw_link" />
    <axis
      xyz="-0.5 0 -0.86603" />    
    <limit
      lower="-1"
      upper="0.2"
      effort="80"
      velocity="10.47" />
  </joint>
  <link
    name="left_thigh_roll_link">
    <inertial>
      <origin
        xyz=" 0.05567763 -0.00167026 -0.03194769"
        rpy="0 0 0" />
      <mass
        value="1.71445955  " />
<inertia ixx="0.00289986" ixy="0.00017144" ixz="0.00326684"
           iyy="0.00916198" iyz="-0.00010134"
           izz="0.00672114"/>
    </inertial>
    <visual>
      <origin
        xyz="0 0 0"
        rpy="0 0 0" />
      <geometry>
        <mesh
          filename="../meshes/left_thigh_roll_link.STL" />
      </geometry>
      <material
        name="">
        <color
          rgba="0.752941176470588 0.752941176470588 0.752941176470588 1" />
      </material>
    </visual>
    <!-- <collision>
      <origin
        xyz="0 0 0"
        rpy="0 0 0" />
      <geometry>
        <mesh
          filename="../meshes/left_thigh_roll_link.STL" />
      </geometry>
    </collision> -->
  </link>
  <joint
    name="left_thigh_roll_joint"
    type="revolute">
    <origin
      xyz="-0.017693 0 -0.072346"
      rpy="0 0 0" />
    <parent
      link="left_thigh_yaw_link" />
    <child
      link="left_thigh_roll_link" />
    <axis
      xyz="0.86603 0 -0.5" />
    <limit
      lower="-0.2"
      upper="1"
      effort="80"
      velocity="10.47" />
  </joint>
  <link
    name="left_thigh_pitch_link">
    <inertial>
      <origin
        xyz=" 0.0001293 -0.0159906 -0.19837385"
        rpy="0 0 0" />
      <mass
        value=" 2.34227381" />
        <inertia ixx="0.11170928" ixy="0.00000310" ixz="0.00008514"
           iyy="0.11203954" iyz="-0.00921446"
           izz="0.00242678"/>
    </inertial>
    <visual>
      <origin
        xyz="0 0 0"
        rpy="0 0 0" />
      <geometry>
        <mesh
          filename="../meshes/left_thigh_pitch_link.STL" />
      </geometry>
      <material
        name="">
        <color
          rgba="0.898039215686275 0.917647058823529 0.929411764705882 1" />
      </material>
    </visual>
    <!-- <collision>
      <origin
        xyz="0 0 0"
        rpy="0 0 0" />
      <geometry>
        <mesh
          filename="../meshes/left_thigh_pitch_link.STL" />
      </geometry>
    </collision> -->
    <collision>
      <origin
        xyz="0.0 0 -0.08"
        rpy="0 0 0" />
      <geometry>
        <box name="left_thigh_pitch_link" size="0.08 0.1 0.22"/>
      </geometry>
    </collision>
  </link>
  <joint
    name="left_thigh_pitch_joint"
    type="revolute">
    <origin
      xyz="0.060622 0.02085 -0.035"
      rpy="0 0 0" />
    <parent
      link="left_thigh_roll_link" />
    <child
      link="left_thigh_pitch_link" />
    <axis
      xyz="0 1 0" />
    <limit
      lower="-1"
      upper="1"
      effort="80"
      velocity="10.47" />
  </joint>
  <link
    name="left_knee_link">
    <inertial>
      <origin
        xyz=" -0.00032236  -0.01193193  -0.14554011"
        rpy="0 0 0" />
      <mass
        value="1.79036871 " />
      <inertia
        ixx="0.05038999"
        ixy="0.00001321"
        ixz="-0.00005627"
        iyy="0.04987102"
        iyz="-0.00346432"
        izz="0.00146349" />
    </inertial>
    <visual>
      <origin
        xyz="0 0 0"
        rpy="0 0 0" />
      <geometry>
        <mesh
          filename="../meshes/left_knee_link.STL" />
      </geometry>
      <material
        name="">
        <color
          rgba="0.898039215686275 0.917647058823529 0.929411764705882 1" />
      </material>
    </visual>
    <!-- <collision>
      <origin
        xyz="0 0 0"
        rpy="0 0 0" />
      <geometry>
        <mesh
          filename="../meshes/left_knee_link.STL" />
      </geometry>
    </collision> -->
    <collision>
      <origin
        xyz="0.0 0 -0.15"
        rpy="0 0 0" />
      <geometry>
        <box name="right_knee_link" size="0.08 0.08 0.22"/>
      </geometry>
    </collision>
  </link>
  <joint
    name="left_knee_joint"
    type="revolute">
    <origin
      xyz="0 0 -0.25"
      rpy="0 0 0" />
    <parent
      link="left_thigh_pitch_link" />
    <child
      link="left_knee_link" />
    <axis
      xyz="0 1 0" />
    <limit
      lower="-0.2"
      upper="2.5"
      effort="80"
      velocity="10.47" />
  </joint>
  <link
    name="left_ankle_pitch_link">
    <inertial>
      <origin
        xyz="0 0 0"
        rpy="0 0 0" />
      <mass
        value="0.084" />
      <inertia
        ixx="0.00000863"
        ixy="0"
        ixz="0"
        iyy="0.00000863"
        iyz="0"
        izz="0.00001448" />
    </inertial>
    <visual>
      <origin
        xyz="0 0 0"
        rpy="0 0 0" />
      <geometry>
        <mesh
          filename="../meshes/left_ankle_pitch_link.STL" />
      </geometry>
      <material
        name="">
        <color
          rgba="1 1 1 1" />
      </material>
    </visual>
    <!-- <collision>
      <origin
        xyz="0 0 0"
        rpy="0 0 0" />
      <geometry>
        <mesh
          filename="../meshes/left_ankle_pitch_link.STL" />
      </geometry>
    </collision> -->
  </link>
  <joint
    name="left_ankle_pitch_joint"
    type="revolute">
    <origin
      xyz="0 -0.02085 -0.3"
      rpy="0 0 0" />
    <parent
      link="left_knee_link" />
    <child
      link="left_ankle_pitch_link" />
    <axis
      xyz="0 1 0" />
    <limit
      lower="-0.6"
      upper="0.6"
      effort="18"
      velocity="3.7692" />
  </joint>
  <link
    name="left_ankle_roll_link">
    <inertial>
      <origin
        xyz="0.01590617  0.00230268 -0.02949007"
        rpy="0 0 0" />
      <mass
        value="0.30640039 " />
      <inertia ixx="0.00038476" ixy="0.0" ixz="0.00017084"
           iyy="0.00086435" iyz="0.00000894"
           izz="0.00063926"/>
    </inertial>
    <visual>
      <origin
        xyz="0 0 0"
        rpy="0 0 0" />
      <geometry>
        <mesh
          filename="../meshes/left_ankle_roll_link.STL" />
      </geometry>
      <material
        name="">
        <color
          rgba="0.898039215686275 0.917647058823529 0.929411764705882 1" />
      </material>
    </visual>
    <collision>
      <origin
        xyz="0 0 0"
        rpy="0 0 0" />
      <geometry>
        <mesh
          filename="../meshes/left_ankle_roll_link.STL" />
      </geometry>
    </collision>
  </link>
  <joint
    name="left_ankle_roll_joint"
    type="revolute">
    <origin
      xyz="0 0 0"
      rpy="0 0 0" />
    <parent
      link="left_ankle_pitch_link" />
    <child
      link="left_ankle_roll_link" />
    <axis
      xyz="1 0 0" />
    <limit
      lower="-0.5"
      upper="0.5"
      effort="18"
      velocity="3.7692" />
  </joint>
  <link
    name="right_thigh_yaw_link">
    <inertial>
      <origin
        xyz="-0.03484738  -0.00011554  -0.05711815"
        rpy="0 0 0" />
      <mass
        value="1.68565743"/>
      <inertia
        ixx="0.007179"
        ixy="-0.00000736"
        ixz="-0.00378571"
        iyy="0.00890804"
        iyz="-0.00001262"
        izz="0.00327044" />
    </inertial>
    <visual>
      <origin
        xyz="0 0 0"
        rpy="0 0 0" />
      <geometry>
        <mesh
          filename="../meshes/right_thigh_yaw_link.STL" />
      </geometry>
      <material
        name="">
        <color
          rgba="0.898039215686275 0.917647058823529 0.929411764705882 1" />
      </material>
    </visual>
    <!-- <collision>
      <origin
        xyz="0 0 0"
        rpy="0 0 0" />
      <geometry>
        <mesh
          filename="../meshes/right_thigh_yaw_link.STL" />
      </geometry>
    </collision> -->
  </link>
  <joint
    name="right_thigh_yaw_joint"
    type="revolute">
    <origin
      xyz="-0.071093 -0.0725 -0.051778"
      rpy="0 0 0" />
    <parent
      link="base_link" />
    <child
      link="right_thigh_yaw_link" />
    <axis
      xyz="-0.5 0 -0.86603" />
    <limit
      lower="-0.2"
      upper="1"
      effort="80"
      velocity="10.47" />
  </joint>
  <link
    name="right_thigh_roll_link">
    <inertial>
      <origin
        xyz="0.05680729 0.00172039 -0.0327877"
        rpy="0 0 0" />
      <mass
        value="1.71072574" />
      <inertia
        ixx="0.00298139"
        ixy="-0.00018165"
        ixz="0.00340107"
        iyy="0.00944463"
        iyz="0.00011011"
        izz="0.00691879" />
    </inertial>
    <visual>
      <origin
        xyz="0 0 0"
        rpy="0 0 0" />
      <geometry>
        <mesh
          filename="../meshes/right_thigh_roll_link.STL" />
      </geometry>
      <material
        name="">
        <color
          rgba="0.898039215686275 0.917647058823529 0.929411764705882 1" />
      </material>
    </visual>
    <!-- <collision>
      <origin
        xyz="0 0 0"
        rpy="0 0 0" />
      <geometry>
        <mesh
          filename="../meshes/right_thigh_roll_link.STL" />
      </geometry>
    </collision> -->
  </link>
  <joint
    name="right_thigh_roll_joint"
    type="revolute">
    <origin
      xyz="-0.0189924084475403 0 -0.0715958163677252"
      rpy="0 0 0" />
    <parent
      link="right_thigh_yaw_link" />
    <child
      link="right_thigh_roll_link" />
    <axis
      xyz="0.86603 0 -0.5" />
    <limit
      lower="-1"
      upper="0.2"
      effort="80"
      velocity="10.47" />
  </joint>
  <link
    name="right_thigh_pitch_link">
    <inertial>
      <origin
        xyz=" -0.00003739 0.01596444  -0.19853624"
        rpy="0 0 0" />
      <mass
        value="2.34600762" />
     <inertia ixx="0.11204629" ixy="0.00000519" ixz="-0.00001381"
           iyy="0.11237751" iyz="0.00921396"
           izz="0.00242783"/>
    </inertial>
    <visual>
      <origin
        xyz="0 0 0"
        rpy="0 0 0" />
      <geometry>
        <mesh
          filename="../meshes/right_thigh_pitch_link.STL" />
      </geometry>
      <material
        name="">
        <color
          rgba="0.898039215686275 0.917647058823529 0.929411764705882 1" />
      </material>
    </visual>
    <!-- <collision>
      <origin
        xyz="0 0 0"
        rpy="0 0 0" />
      <geometry>
        <mesh
          filename="../meshes/right_thigh_pitch_link.STL" />
      </geometry>
    </collision> -->
     <collision>
      <origin
        xyz="0.0 0 -0.08"
        rpy="0 0 0" />
      <geometry>
        <box name="right_thigh_pitch_link" size="0.08 0.1 0.22"/>
      </geometry>
    </collision>
  </link>
  <joint
    name="right_thigh_pitch_joint"
    type="revolute">
    <origin
      xyz="0.0619208163652291 -0.0208499999999942 -0.0357500000093095"
      rpy="0 0 0" />
    <parent
      link="right_thigh_roll_link" />
    <child
      link="right_thigh_pitch_link" />
    <axis
      xyz="0 1 0" />
    <limit
      lower="-1"
      upper="1"
      effort="80"
      velocity="10.47" />
  </joint>
  <link
    name="right_knee_link">
    <inertial>
      <origin
        xyz="0.00033538 0.01192569 -0.14552664"
        rpy="0 0 0" />
      <mass
        value=" 1.79131378" />
      <inertia ixx="0.05040361" ixy="0.00001321" ixz="0.00005910"
           iyy="0.04988522" iyz="0.00346433"
           izz="0.00146409"/>
    </inertial>
    <visual>
      <origin
        xyz="0 0 0"
        rpy="0 0 0" />
      <geometry>
        <mesh
          filename="../meshes/right_knee_link.STL" />
      </geometry>
      <material
        name="">
        <color
          rgba="0.898039215686275 0.917647058823529 0.929411764705882 1" />
      </material>
    </visual>
    <!-- <collision>
      <origin
        xyz="0 0 0"
        rpy="0 0 0" />
      <geometry>
        <mesh
          filename="../meshes/right_knee_link.STL" />
      </geometry>
    </collision> -->
    <collision>
      <origin
        xyz="0.0 0 -0.15"
        rpy="0 0 0" />
      <geometry>
        <box name="right_knee_link" size="0.08 0.08 0.22"/>
      </geometry>
    </collision>
  </link>
  <joint
    name="right_knee_joint"
    type="revolute">
    <origin
      xyz="0 0 -0.250000000000016"
      rpy="0 0 0" />
    <parent
      link="right_thigh_pitch_link" />
    <child
      link="right_knee_link" />
    <axis
      xyz="0 1 0" />
    <limit
      lower="-0.2"
      upper="2.5"
      effort="80"
      velocity="10.47" />
  </joint>
  <link
    name="right_ankle_pitch_link">
    <inertial>
      <origin
        xyz="0 0 0"
        rpy="0 0 0" />
      <mass
        value="0.084" />
      <inertia
        ixx="0.00000863"
        ixy="0"
        ixz="0"
        iyy="0.00000863"
        iyz="0"
        izz="0.00001448" />
    </inertial>
    <visual>
      <origin
        xyz="0 0 0"
        rpy="0 0 0" />
      <geometry>
        <mesh
          filename="../meshes/right_ankle_pitch_link.STL" />
      </geometry>
      <material
        name="">
        <color
          rgba="1 1 1 1" />
      </material>
    </visual>
    <!-- <collision>
      <origin
        xyz="0 0 0"
        rpy="0 0 0" />
      <geometry>
        <mesh
          filename="../meshes/right_ankle_pitch_link.STL" />
      </geometry>
    </collision> -->
  </link>
  <joint
    name="right_ankle_pitch_joint"
    type="revolute">
    <origin
      xyz="0 0.0208500000000073 -0.299999999999986"
      rpy="0 0 0" />
    <parent
      link="right_knee_link" />
    <child
      link="right_ankle_pitch_link" />
    <axis
      xyz="0 1 0" />
    <limit
      lower="-0.6"
      upper="0.6"
      effort="18"
      velocity="3.7692" />
  </joint>
  <link
    name="right_ankle_roll_link">
    <inertial>
      <origin
        xyz="0.01590617 -0.00230290  -0.02949007"
        rpy="0 0 0" />
      <mass
        value=" 0.30640039" />
       <inertia ixx="0.00038476" ixy="0.00000000" ixz="0.00017084"
           iyy="0.00086435" iyz="-0.00000894"
           izz="0.00063926"/>
    </inertial>
    <visual>
      <origin
        xyz="0 0 0"
        rpy="0 0 0" />
      <geometry>
        <mesh
          filename="../meshes/right_ankle_roll_link.STL" />
      </geometry>
      <material
        name="">
        <color
          rgba="0.898039215686275 0.917647058823529 0.929411764705882 1" />
      </material>
    </visual>
    <collision>
      <origin
        xyz="0 0 0"
        rpy="0 0 0" />
      <geometry>
        <mesh
          filename="../meshes/right_ankle_roll_link.STL" />
      </geometry>
    </collision>
  </link>
  <joint
    name="right_ankle_roll_joint"
    type="revolute">
    <origin
      xyz="0 0 0"
      rpy="0 0 0" />
    <parent
      link="right_ankle_pitch_link" />
    <child
      link="right_ankle_roll_link" />
    <axis
      xyz="1 0 0" />
    <limit
      lower="-0.5"
      upper="0.5"
      effort="18"
      velocity="3.7692" />
  </joint>
  <link
    name="torso_link">
    <inertial>
      <origin
        xyz=" -0.00232713 -0.00003499 0.09671181"
        rpy="0 0 0" />
      <mass
        value="7.70005232 " />
       <inertia ixx="0.14285885" ixy="-0.00004101" ixz="0.00400640"
           iyy="0.13043257" iyz="0.00003257"
           izz="0.03968469"/>
    </inertial>
    <visual>
      <origin
        xyz="0 0 0"
        rpy="0 0 0" />
      <geometry>
        <mesh
          filename="../meshes/torso_link.STL" />
      </geometry>
      <material
        name="">
        <color
          rgba="1 1 1 1" />
      </material>
    </visual>
    <collision>
      <origin
        xyz="0 0 0.15"
        rpy="0 0 0" />
      <geometry>
        <box name="torso_link" size="0.16 0.16 0.22"/>
      </geometry>
    </collision>
  </link>
  <joint
    name="torso_joint"
    type="revolute">
    <origin
      xyz="-0.0281649492242451 0 0.0672000000054882"
      rpy="0 0 0" />
    <parent
      link="base_link" />
    <child
      link="torso_link" />
    <axis
      xyz="0 0 1" />
    <limit
      lower="-3.14"
      upper="3.14"
      effort="80"
      velocity="10.47" />
  </joint>
  <link
    name="left_arm_pitch_link">
    <inertial>
      <origin
        xyz=" -0.00335473 0.04998761 0.00007446"
        rpy="0 0 0" />
      <mass
        value="0.47050957" />
       <inertia ixx="0.00136600" ixy="0.00009678" ixz="-0.00000066"
           iyy="0.00011898" iyz="-0.00000154"
           izz="0.00140010"/>
    </inertial>
    <visual>
      <origin
        xyz="0 0 0"
        rpy="0 0 0" />
      <geometry>
        <mesh
          filename="../meshes/left_arm_pitch_link.STL" />
      </geometry>
      <material
        name="">
        <color
          rgba="0.796078431372549 0.823529411764706 0.937254901960784 1" />
      </material>
    </visual>
    <collision>
      <origin
        xyz="0 0.055 0"
        rpy="0 1.57 0" />
      <geometry>
         <cylinder radius="0.03" length="0.05"/>
      </geometry>
    </collision>
  </link>
  <joint
    name="left_arm_pitch_joint"
    type="revolute">
    <origin
      xyz="0 0.121749999999383 0.206175860782433"
      rpy="0 0 0" />
    <parent
      link="torso_link" />
    <child
      link="left_arm_pitch_link" />
    <axis
      xyz="0 1 0" />
    <limit
      lower="-1.57"
      upper="1.57"
      effort="18"
      velocity="3.7692" />
  </joint>
  <link
    name="left_arm_roll_link">
    <inertial>
      <origin
        xyz="-0.00433076 0 -0.02378501"
        rpy="0 0 0" />
      <mass
        value="0.09168685" />
     <inertia ixx="0.00010210" ixy="0.0" ixz="-0.00002948"
           iyy="0.00011636" iyz="0.0"
           izz="0.00003231"/>
    </inertial>
    <visual>
      <origin
        xyz="0 0 0"
        rpy="0 0 0" />
      <geometry>
        <mesh
          filename="../meshes/left_arm_roll_link.STL" />
      </geometry>
      <material
        name="">
        <color
          rgba="0.796078431372549 0.823529411764706 0.937254901960784 1" />
      </material>
    </visual>
    <collision>
      <origin
        xyz="-0.02 0 -0.12"
        rpy="0 0 0" />
      <geometry>
         <cylinder radius="0.03" length="0.10"/>
      </geometry>
    </collision>
  </link>
  <joint
    name="left_arm_roll_joint"
    type="revolute">
    <origin
      xyz="0.0200000000000018 0.056 0"
      rpy="0 0 0" />
    <parent
      link="left_arm_pitch_link" />
    <child
      link="left_arm_roll_link" />
    <axis
      xyz="1 0 0" />
    <limit
      lower="-0.25"
      upper="1"
      effort="18"
      velocity="3.7692" />
  </joint>
  <link
    name="left_arm_yaw_link">
    <inertial>
      <origin
        xyz=" -0.00005620  -0.00138987 -0.10567955"
        rpy="0 0 0" />
      <mass
        value="1.15324429" />
      <inertia ixx="0.01922317" ixy="-0.00000022" ixz="-0.00000659"
           iyy="0.01918946" iyz="-0.00030586"
           izz="0.00040127"/>
    </inertial>
    <visual>
      <origin
        xyz="0 0 0"
        rpy="0 0 0" />
      <geometry>
        <mesh
          filename="../meshes/left_arm_yaw_link.STL" />
      </geometry>
      <material
        name="">
        <color
          rgba="0.796078431372549 0.823529411764706 0.937254901960784 1" />
      </material>
    </visual>
    <collision>
      <origin
        xyz="0 0 -0.19"
        rpy="0 1.57 1.57" />
      <geometry>
        <cylinder radius="0.03" length="0.05"/>
      </geometry>
    </collision>
  </link>
  <joint
    name="left_arm_yaw_joint"
    type="revolute">
    <origin
      xyz="-0.0200000000000002 0 -0.049999999999998"
      rpy="0 0 0" />
    <parent
      link="left_arm_roll_link" />
    <child
      link="left_arm_yaw_link" />
    <axis
      xyz="0 0 -1" />
    <limit
      lower="-1.57"
      upper="1.57"
      effort="18"
      velocity="3.7692" />
  </joint>
  <link
    name="left_elbow_pitch_link">
    <inertial>
      <origin
        xyz="0.02378501 -0.00433076  0.00000000"
        rpy="0 0 0" />
      <mass
        value="0.09168685" />
       <inertia ixx="0.00003231" ixy="0.00002948" ixz="0.0"
           iyy="0.00010210" iyz="0.0"
           izz="0.00011636"/>
    </inertial>
    <visual>
      <origin
        xyz="0 0 0"
        rpy="0 0 0" />
      <geometry>
        <mesh
          filename="../meshes/left_elbow_pitch_link.STL" />
      </geometry>
      <material
        name="">
        <color
          rgba="0.796078431372549 0.823529411764706 0.937254901960784 1" />
      </material>
    </visual>
    <collision>
      <origin
        xyz="0.10 -0.02 0"
        rpy="0 1.57 0" />
      <geometry>
          <cylinder radius="0.03" length="0.10"/>
      </geometry>
    </collision>
  </link>
  <joint
    name="left_elbow_pitch_joint"
    type="revolute">
    <origin
      xyz="0 0.0199999999999982 -0.188749999999997"
      rpy="0 0 0" />
    <parent
      link="left_arm_yaw_link" />
    <child
      link="left_elbow_pitch_link" />
    <axis
      xyz="0 1 0" />
    <limit
      lower="-0.6"
      upper="1.57"
      effort="18"
      velocity="3.7692" />
  </joint>
  <link
    name="left_elbow_yaw_link">
    <inertial>
      <origin
        xyz="0.05240866 -0.00007821 -0.00001993"
        rpy="0 0 0" />
      <mass
        value="0.68145673 " />
     <inertia ixx="0.00028205" ixy="0.00000224" ixz="0.00000058"
           iyy="0.00326107" iyz="-0.00000061"
           izz="0.00326218"/>
    </inertial>
    <visual>
      <origin
        xyz="0 0 0"
        rpy="0 0 0" />
      <geometry>
        <mesh
          filename="../meshes/left_elbow_yaw_link.STL" />
      </geometry>
      <material
        name="">
        <color
          rgba="0.796078431372549 0.823529411764706 0.937254901960784 1" />
      </material>
    </visual>
    <!-- <collision>
      <origin
        xyz="0 0 0"
        rpy="0 0 0" />
      <geometry>
        <mesh
          filename="../meshes/left_elbow_yaw_link.STL" />
      </geometry>
    </collision> -->
  </link>
  <joint
    name="left_elbow_yaw_joint"
    type="revolute">
    <origin
      xyz="0.0499999999999968 -0.0199999999999994 0"
      rpy="0 0 0" />
    <parent
      link="left_elbow_pitch_link" />
    <child
      link="left_elbow_yaw_link" />
    <axis
      xyz="1 0 0" />
    <limit
      lower="-1.57"
      upper="1.57"
      effort="18"
      velocity="3.7692" />
  </joint>
  <link
    name="right_arm_pitch_link">
    <inertial>
      <origin
        xyz=" -0.00331397  -0.04987479 0.00005595"
        rpy="0 0 0" />
      <mass
        value="0.47178757" />
      <inertia ixx="0.00136619" ixy="-0.00009666" ixz="-0.00000056"
           iyy="0.00011922" iyz="0.00000149"
           izz="0.00140040"/>
    </inertial>
    <visual>
      <origin
        xyz="0 0 0"
        rpy="0 0 0" />
      <geometry>
        <mesh
          filename="../meshes/right_arm_pitch_link.STL" />
      </geometry>
      <material
        name="">
        <color
          rgba="1 1 1 1" />
      </material>
    </visual>
    <collision>
      <origin
        xyz="0 -0.055 0"
        rpy="0 1.57 0" />
      <geometry>
         <cylinder radius="0.03" length="0.05"/>
      </geometry>
    </collision>
  </link>
  <joint
    name="right_arm_pitch_joint"
    type="revolute">
    <origin
      xyz="0 -0.121750000000346 0.206175860781721"
      rpy="0 0 0" />
    <parent
      link="torso_link" />
    <child
      link="right_arm_pitch_link" />
    <axis
      xyz="0 1 0" />
    <limit
      lower="-1.57"
      upper="1.57"
      effort="18"
      velocity="3.7692" />
  </joint>
  <link
    name="right_arm_roll_link">
    <inertial>
      <origin
        xyz="-0.00433076 0.00000000  -0.02378501"
        rpy="0 0 0" />
      <mass
        value="0.09168685" />
 <inertia ixx="0.00010210" ixy="0.0" ixz="-0.00002948"
           iyy="0.00011636" iyz="0.0"
           izz="0.00003231"/>
    </inertial>
    <visual>
      <origin
        xyz="0 0 0"
        rpy="0 0 0" />
      <geometry>
        <mesh
          filename="../meshes/right_arm_roll_link.STL" />
      </geometry>
      <material
        name="">
        <color
          rgba="0.796078431372549 0.823529411764706 0.937254901960784 1" />
      </material>
    </visual>
     <collision>
      <origin
        xyz="-0.02 0 -0.12"
        rpy="0 0 0" />
      <geometry>
         <cylinder radius="0.03" length="0.10"/>
      </geometry>
    </collision>
  </link>
  <joint
    name="right_arm_roll_joint"
    type="revolute">
    <origin
      xyz="0.0200000000000407 -0.056 0"
      rpy="0 0 0" />
    <parent
      link="right_arm_pitch_link" />
    <child
      link="right_arm_roll_link" />
    <axis
      xyz="1 0 0" />
    <limit
      lower="-1"
      upper="0.25"
      effort="18"
      velocity="3.7692" />
  </joint>
  <link
    name="right_arm_yaw_link">
    <inertial>
      <origin
        xyz="-0.00004333  0.00141617  -0.10564026"
        rpy="0 0 0" />
      <mass
        value="1.15196629" />
     <inertia ixx="0.01919858" ixy="-0.00000049" ixz="-0.00000683"
           iyy="0.01916287" iyz="0.00030855"
           izz="0.00040103"/>
    </inertial>
    <visual>
      <origin
        xyz="0 0 0"
        rpy="0 0 0" />
      <geometry>
        <mesh
          filename="../meshes/right_arm_yaw_link.STL" />
      </geometry>
      <material
        name="">
        <color
          rgba="0.796078431372549 0.823529411764706 0.937254901960784 1" />
      </material>
    </visual>
    <collision>
      <origin
        xyz="0 0 -0.19"
        rpy="0 1.57 1.57" />
      <geometry>
        <cylinder radius="0.03" length="0.05"/>
      </geometry>
    </collision>
  </link>
  <joint
    name="right_arm_yaw_joint"
    type="revolute">
    <origin
      xyz="-0.02 0 -0.0500000000000019"
      rpy="0 0 0" />
    <parent
      link="right_arm_roll_link" />
    <child
      link="right_arm_yaw_link" />
    <axis
      xyz="0 0 -1" />
    <limit
      lower="-1.57"
      upper="1.57"
      effort="18"
      velocity="3.7692" />
  </joint>
  <link
    name="right_elbow_pitch_link">
    <inertial>
      <origin
        xyz="0.02378501  0.00433076 0"
        rpy="0 0 0" />
      <mass
        value="0.09168685" />
      <inertia ixx="0.00003231" ixy="-0.00002948" ixz="0.0"
           iyy="0.00010210" iyz="0.0"
           izz="0.00011636"/>
    </inertial>
    <visual>
      <origin
        xyz="0 0 0"
        rpy="0 0 0" />
      <geometry>
        <mesh
          filename="../meshes/right_elbow_pitch_link.STL" />
      </geometry>
      <material
        name="">
        <color
          rgba="0.796078431372549 0.823529411764706 0.937254901960784 1" />
      </material>
    </visual>
    <collision>
      <origin
        xyz="0.10 0.02 0"
        rpy="0 1.57 0" />
      <geometry>
          <cylinder radius="0.03" length="0.10"/>
      </geometry>
    </collision>
  </link>
  <joint
    name="right_elbow_pitch_joint"
    type="revolute">
    <origin
      xyz="0 -0.0200000000000019 -0.18875"
      rpy="0 0 0" />
    <parent
      link="right_arm_yaw_link" />
    <child
      link="right_elbow_pitch_link" />
    <axis
      xyz="0 1 0" />
    <limit
      lower="-0.6"
      upper="1.57"
      effort="18"
      velocity="3.7692" />
  </joint>
  <link
    name="right_elbow_yaw_link">
    <inertial>
      <origin
        xyz="0.05240866 0.00007821 0.00001993"
        rpy="0 0 0" />
      <mass
        value="0.68145673" />
      <inertia
        ixx="0.00028205"
        ixy="-0.00000224"
        ixz="-0.00000058"
        iyy="0.00326107"
        iyz="-0.00000061"
        izz=" 0.00326218" />
    </inertial>
    <visual>
      <origin
        xyz="0 0 0"
        rpy="0 0 0" />
      <geometry>
        <mesh
          filename="../meshes/right_elbow_yaw_link.STL" />
      </geometry>
      <material
        name="">
        <color
          rgba="1 1 1 1" />
      </material>
    </visual>
    <!-- <collision>
      <origin
        xyz="0 0 0"
        rpy="0 0 0" />
      <geometry>
        <mesh
          filename="../meshes/right_elbow_yaw_link.STL" />
      </geometry>
    </collision> -->
  </link>
  <joint
    name="right_elbow_yaw_joint"
    type="revolute">
    <origin
      xyz="0.0500000000000002 0.0200000000000004 0"
      rpy="0 0 0" />
    <parent
      link="right_elbow_pitch_link" />
    <child
      link="right_elbow_yaw_link" />
    <axis
      xyz="1 0 0" />
    <limit
      lower="-1.57"
      upper="1.57"
      effort="18"
      velocity="3.7692" />
  </joint>
</robot>